<?xml version="1.0" ?>
<!-- =================================================================================== -->
<!-- |    This document was autogenerated by xacro from noir_description/urdf/noir_base.xacro | -->
<!-- |    EDITING THIS FILE BY HAND IS NOT RECOMMENDED                                 | -->
<!-- =================================================================================== -->
<robot name="noir" xmlns:xacro="http://ros.org/wiki/xacro">
  <link name="base_link"/>
  <joint name="base_joint" type="fixed">
    <origin rpy="0 0 0" xyz="0 0 0"/>
    <parent link="base_link"/>
    <child link="base_link_inertia"/>
  </joint>
  <link name="base_link_inertia">
    <inertial>
      <mass value="5"/>
      <!-- [kg] -->
      <origin xyz="0 0 0"/>
      <inertia ixx="0.0347563" ixy="0.0" ixz="0.0" iyy="0.0458929" iyz="0.0" izz="0.0977"/>
    </inertial>
    <visual>
      <origin rpy="0 0 0" xyz="0 0 0"/>
      <geometry>
        <mesh filename="model://noir_description/meshes/CF_assembly.stl" scale="1 1 1"/>
        <!-- <box size="${body_width} ${body_width} ${body_height}"/> -->
        <!-- [m] [m] [m] -->
      </geometry>
    </visual>
    <collision>
      <origin rpy="0 0 0" xyz="0 0 0"/>
      <geometry>
        <box size="1.05 1.05 0.2"/>
        <!-- [m] [m] [m] -->
      </geometry>
    </collision>
  </link>
  <!-- attach multirotor_base_plugin to the base_link -->
  <gazebo>
    <plugin filename="librotors_gazebo_multirotor_base_plugin.so" name="rosbag">
      <robotNamespace></robotNamespace>
      <linkName>base_link</linkName>
      <rotorVelocitySlowdownSim>10</rotorVelocitySlowdownSim>
    </plugin>
  </gazebo>
  <gazebo reference="base_link">
    <material>Gazebo/DarkGrey</material>
    <collision name="base_link_inertia_collision">
      <surface>
        <contact>
          <ode>
            <min_depth>0.001</min_depth>
            <max_vel>0.0</max_vel>
          </ode>
        </contact>
        <friction>
          <ode/>
        </friction>
      </surface>
    </collision>
  </gazebo>
  <joint name="rotor_0_joint" type="continuous">
    <origin rpy="0 0 0" xyz="0.265 -0.265 0.078"/>
    <axis xyz="0 0 1"/>
    <!-- TODO(ff): not currently set because it's not yet supported -->
    <!-- <limit effort="2000" velocity="${max_rot_velocity}" /> -->
    <parent link="base_link"/>
    <child link="rotor_0"/>
  </joint>
  <!-- TODO(ff): not currently set because it's not yet supported -->
  <!-- <gazebo reference="rotor_${motor_number}_joint"> <axis> <xyz>0 0 1</xyz>
      <limit> <velocity> ${max_rot_velocity} </velocity> </limit> </axis> </gazebo> -->
  <link name="rotor_0">
    <inertial>
      <mass value="0.05"/>
      <!-- [kg] -->
      <inertia ixx="9.75e-06" ixy="0.0" ixz="0.0" iyy="0.008710035" iyz="0.0" izz="0.008719035"/>
    </inertial>
    <visual>
      <geometry>
        <!-- <cylinder length="0.005" radius="${radius_rotor}"/> -->
        <!-- [m] -->
        <!-- <mesh filename="package://rotors_description/meshes/propeller_${direction}.dae" -->
        <mesh filename="model://noir_description/meshes/prop18.stl" scale="1 1 1"/>
        <!-- <box size="${2*radius_rotor} 0.01 0.005"/> -->
      </geometry>
    </visual>
    <collision>
      <geometry>
        <cylinder length="0.005" radius="0.2286"/>
        <!-- [m] -->
      </geometry>
    </collision>
  </link>
  <gazebo>
    <plugin filename="librotors_gazebo_motor_model.so" name="front_right_motor_model">
      <robotNamespace></robotNamespace>
      <jointName>rotor_0_joint</jointName>
      <linkName>rotor_0</linkName>
      <turningDirection>ccw</turningDirection>
      <timeConstantUp>0.025</timeConstantUp>
      <timeConstantDown>0.05</timeConstantDown>
      <maxRotVelocity>565.486677646</maxRotVelocity>
      <motorConstant>7.974352e-05</motorConstant>
      <momentConstant>0.02893726238</momentConstant>
      <commandSubTopic>/gazebo/command/motor_speed</commandSubTopic>
      <motorNumber>0</motorNumber>
      <rotorDragCoefficient>0.000806428</rotorDragCoefficient>
      <rollingMomentCoefficient>1e-06</rollingMomentCoefficient>
      <motorSpeedPubTopic>/motor_speed/0</motorSpeedPubTopic>
      <rotorVelocitySlowdownSim>10</rotorVelocitySlowdownSim>
      <!--
        <gazebo_joint_control_pid>
          <p>0.1</p>
          <i>0</i>
          <d>0</d>
          <iMax>0</iMax>
          <iMin>0</iMin>
          <cmdMax>3</cmdMax>
          <cmdMin>-3</cmdMin>
        </gazebo_joint_control_pid>
      -->
    </plugin>
  </gazebo>
  <gazebo reference="rotor_0">
    <material>Gazebo/Blue</material>
  </gazebo>
  <joint name="rotor_1_joint" type="continuous">
    <origin rpy="0 0 0" xyz="-0.265 0.265 0.078"/>
    <axis xyz="0 0 1"/>
    <!-- TODO(ff): not currently set because it's not yet supported -->
    <!-- <limit effort="2000" velocity="${max_rot_velocity}" /> -->
    <parent link="base_link"/>
    <child link="rotor_1"/>
  </joint>
  <!-- TODO(ff): not currently set because it's not yet supported -->
  <!-- <gazebo reference="rotor_${motor_number}_joint"> <axis> <xyz>0 0 1</xyz>
      <limit> <velocity> ${max_rot_velocity} </velocity> </limit> </axis> </gazebo> -->
  <link name="rotor_1">
    <inertial>
      <mass value="0.05"/>
      <!-- [kg] -->
      <inertia ixx="9.75e-06" ixy="0.0" ixz="0.0" iyy="0.008710035" iyz="0.0" izz="0.008719035"/>
    </inertial>
    <visual>
      <geometry>
        <!-- <cylinder length="0.005" radius="${radius_rotor}"/> -->
        <!-- [m] -->
        <!-- <mesh filename="package://rotors_description/meshes/propeller_${direction}.dae" -->
        <mesh filename="model://noir_description/meshes/prop18.stl" scale="1 1 1"/>
        <!-- <box size="${2*radius_rotor} 0.01 0.005"/> -->
      </geometry>
    </visual>
    <collision>
      <geometry>
        <cylinder length="0.005" radius="0.2286"/>
        <!-- [m] -->
      </geometry>
    </collision>
  </link>
  <gazebo>
    <plugin filename="librotors_gazebo_motor_model.so" name="back_left_motor_model">
      <robotNamespace></robotNamespace>
      <jointName>rotor_1_joint</jointName>
      <linkName>rotor_1</linkName>
      <turningDirection>ccw</turningDirection>
      <timeConstantUp>0.025</timeConstantUp>
      <timeConstantDown>0.05</timeConstantDown>
      <maxRotVelocity>565.486677646</maxRotVelocity>
      <motorConstant>7.974352e-05</motorConstant>
      <momentConstant>0.02893726238</momentConstant>
      <commandSubTopic>/gazebo/command/motor_speed</commandSubTopic>
      <motorNumber>1</motorNumber>
      <rotorDragCoefficient>0.000806428</rotorDragCoefficient>
      <rollingMomentCoefficient>1e-06</rollingMomentCoefficient>
      <motorSpeedPubTopic>/motor_speed/1</motorSpeedPubTopic>
      <rotorVelocitySlowdownSim>10</rotorVelocitySlowdownSim>
      <!--
        <gazebo_joint_control_pid>
          <p>0.1</p>
          <i>0</i>
          <d>0</d>
          <iMax>0</iMax>
          <iMin>0</iMin>
          <cmdMax>3</cmdMax>
          <cmdMin>-3</cmdMin>
        </gazebo_joint_control_pid>
      -->
    </plugin>
  </gazebo>
  <gazebo reference="rotor_1">
    <material>Gazebo/DarkGrey</material>
  </gazebo>
  <joint name="rotor_2_joint" type="continuous">
    <origin rpy="0 0 0" xyz="0.265 0.265 0.078"/>
    <axis xyz="0 0 1"/>
    <!-- TODO(ff): not currently set because it's not yet supported -->
    <!-- <limit effort="2000" velocity="${max_rot_velocity}" /> -->
    <parent link="base_link"/>
    <child link="rotor_2"/>
  </joint>
  <!-- TODO(ff): not currently set because it's not yet supported -->
  <!-- <gazebo reference="rotor_${motor_number}_joint"> <axis> <xyz>0 0 1</xyz>
      <limit> <velocity> ${max_rot_velocity} </velocity> </limit> </axis> </gazebo> -->
  <link name="rotor_2">
    <inertial>
      <mass value="0.05"/>
      <!-- [kg] -->
      <inertia ixx="9.75e-06" ixy="0.0" ixz="0.0" iyy="0.008710035" iyz="0.0" izz="0.008719035"/>
    </inertial>
    <visual>
      <geometry>
        <!-- <cylinder length="0.005" radius="${radius_rotor}"/> -->
        <!-- [m] -->
        <!-- <mesh filename="package://rotors_description/meshes/propeller_${direction}.dae" -->
        <mesh filename="model://noir_description/meshes/prop18.stl" scale="1 1 1"/>
        <!-- <box size="${2*radius_rotor} 0.01 0.005"/> -->
      </geometry>
    </visual>
    <collision>
      <geometry>
        <cylinder length="0.005" radius="0.2286"/>
        <!-- [m] -->
      </geometry>
    </collision>
  </link>
  <gazebo>
    <plugin filename="librotors_gazebo_motor_model.so" name="front_left_motor_model">
      <robotNamespace></robotNamespace>
      <jointName>rotor_2_joint</jointName>
      <linkName>rotor_2</linkName>
      <turningDirection>cw</turningDirection>
      <timeConstantUp>0.025</timeConstantUp>
      <timeConstantDown>0.05</timeConstantDown>
      <maxRotVelocity>565.486677646</maxRotVelocity>
      <motorConstant>7.974352e-05</motorConstant>
      <momentConstant>0.02893726238</momentConstant>
      <commandSubTopic>/gazebo/command/motor_speed</commandSubTopic>
      <motorNumber>2</motorNumber>
      <rotorDragCoefficient>0.000806428</rotorDragCoefficient>
      <rollingMomentCoefficient>1e-06</rollingMomentCoefficient>
      <motorSpeedPubTopic>/motor_speed/2</motorSpeedPubTopic>
      <rotorVelocitySlowdownSim>10</rotorVelocitySlowdownSim>
      <!--
        <gazebo_joint_control_pid>
          <p>0.1</p>
          <i>0</i>
          <d>0</d>
          <iMax>0</iMax>
          <iMin>0</iMin>
          <cmdMax>3</cmdMax>
          <cmdMin>-3</cmdMin>
        </gazebo_joint_control_pid>
      -->
    </plugin>
  </gazebo>
  <gazebo reference="rotor_2">
    <material>Gazebo/Blue</material>
  </gazebo>
  <joint name="rotor_3_joint" type="continuous">
    <origin rpy="0 0 0" xyz="-0.265 -0.265 0.078"/>
    <axis xyz="0 0 1"/>
    <!-- TODO(ff): not currently set because it's not yet supported -->
    <!-- <limit effort="2000" velocity="${max_rot_velocity}" /> -->
    <parent link="base_link"/>
    <child link="rotor_3"/>
  </joint>
  <!-- TODO(ff): not currently set because it's not yet supported -->
  <!-- <gazebo reference="rotor_${motor_number}_joint"> <axis> <xyz>0 0 1</xyz>
      <limit> <velocity> ${max_rot_velocity} </velocity> </limit> </axis> </gazebo> -->
  <link name="rotor_3">
    <inertial>
      <mass value="0.05"/>
      <!-- [kg] -->
      <inertia ixx="9.75e-06" ixy="0.0" ixz="0.0" iyy="0.008710035" iyz="0.0" izz="0.008719035"/>
    </inertial>
    <visual>
      <geometry>
        <!-- <cylinder length="0.005" radius="${radius_rotor}"/> -->
        <!-- [m] -->
        <!-- <mesh filename="package://rotors_description/meshes/propeller_${direction}.dae" -->
        <mesh filename="model://noir_description/meshes/prop18.stl" scale="1 1 1"/>
        <!-- <box size="${2*radius_rotor} 0.01 0.005"/> -->
      </geometry>
    </visual>
    <collision>
      <geometry>
        <cylinder length="0.005" radius="0.2286"/>
        <!-- [m] -->
      </geometry>
    </collision>
  </link>
  <gazebo>
    <plugin filename="librotors_gazebo_motor_model.so" name="back_right_motor_model">
      <robotNamespace></robotNamespace>
      <jointName>rotor_3_joint</jointName>
      <linkName>rotor_3</linkName>
      <turningDirection>cw</turningDirection>
      <timeConstantUp>0.025</timeConstantUp>
      <timeConstantDown>0.05</timeConstantDown>
      <maxRotVelocity>565.486677646</maxRotVelocity>
      <motorConstant>7.974352e-05</motorConstant>
      <momentConstant>0.02893726238</momentConstant>
      <commandSubTopic>/gazebo/command/motor_speed</commandSubTopic>
      <motorNumber>3</motorNumber>
      <rotorDragCoefficient>0.000806428</rotorDragCoefficient>
      <rollingMomentCoefficient>1e-06</rollingMomentCoefficient>
      <motorSpeedPubTopic>/motor_speed/3</motorSpeedPubTopic>
      <rotorVelocitySlowdownSim>10</rotorVelocitySlowdownSim>
      <!--
        <gazebo_joint_control_pid>
          <p>0.1</p>
          <i>0</i>
          <d>0</d>
          <iMax>0</iMax>
          <iMin>0</iMin>
          <cmdMax>3</cmdMax>
          <cmdMin>-3</cmdMin>
        </gazebo_joint_control_pid>
      -->
    </plugin>
  </gazebo>
  <gazebo reference="rotor_3">
    <material>Gazebo/DarkGrey</material>
  </gazebo>
  <link name="/camera_front_left_optical_link">
    <collision>
      <origin rpy="0 0 0" xyz="0 0 0"/>
      <geometry>
        <cylinder length="0.04" radius="0.04"/>
      </geometry>
    </collision>
    <visual>
      <origin rpy="0 1.57079632679 0" xyz="0 0 0"/>
      <geometry>
        <cylinder length="0.04" radius="0.04"/>
      </geometry>
      <material name="red"/>
    </visual>
    <inertial>
      <mass value="1e-5"/>
      <origin rpy="0 0 0" xyz="0 0 0"/>
      <inertia ixx="1e-6" ixy="0" ixz="0" iyy="1e-6" iyz="0" izz="1e-6"/>
    </inertial>
  </link>
  <joint name="/camera_front_left_optical_joint" type="fixed">
    <origin rpy="0 0 0" xyz="0 0 0.4"/>
    <parent link="base_link"/>
    <child link="/camera_front_left_optical_link"/>
  </joint>
  <link name="/camera_front_right_optical_link">
    <collision>
      <origin rpy="0 0 0" xyz="0 0 0"/>
      <geometry>
        <cylinder length="0.04" radius="0.04"/>
      </geometry>
    </collision>
    <visual>
      <origin rpy="0 1.57079632679 0" xyz="0 0 0"/>
      <geometry>
        <cylinder length="0.04" radius="0.04"/>
      </geometry>
      <material name="red"/>
    </visual>
    <inertial>
      <mass value="1e-5"/>
      <origin rpy="0 0 0" xyz="0 0 0"/>
      <inertia ixx="1e-6" ixy="0" ixz="0" iyy="1e-6" iyz="0" izz="1e-6"/>
    </inertial>
  </link>
  <joint name="/camera_front_right_optical_joint" type="fixed">
    <origin rpy="0 0 0" xyz="0 -0.076 0"/>
    <parent link="/camera_front_left_optical_link"/>
    <child link="/camera_front_right_optical_link"/>
  </joint>
  <gazebo reference="/camera_front_left_optical_link">
    <sensor name="stereo_camera" type="multicamera">
      <!-- see MultiSenseSLPlugin.h for available modes -->
      <update_rate>30.0</update_rate>
      <camera name="left">
        <!-- Spec sheet says 80deg X 45deg @ 1024x544pix.  Based on feedback
	    from teams, we're instead doing 80deg X 80deg @ 800x800pix. -->
        <horizontal_fov>1.3962634</horizontal_fov>
        <image>
          <width>752</width>
          <height>480</height>
          <format>R8G8B8</format>
        </image>
        <clip>
          <near>0.02</near>
          <far>100</far>
        </clip>
      </camera>
      <camera name="right">
        <pose>0 -0.076 0 0 0 0</pose>
        <!-- Spec sheet says 80deg X 45deg @ 1024x544pix.  Based on feedback
	    from teams, we're instead doing 80deg X 80deg @ 800x800pix. -->
        <horizontal_fov>1.3962634</horizontal_fov>
        <image>
          <width>752</width>
          <height>480</height>
          <format>R8G8B8</format>
        </image>
        <clip>
          <near>0.02</near>
          <far>100</far>
        </clip>
      </camera>
      <plugin filename="libgazebo_ros_multicamera.so" name="stereo_camera_controller">
        <alwaysOn>true</alwaysOn>
        <updateRate>0.0</updateRate>
        <cameraName>camera_front</cameraName>
        <imageTopicName>image_raw</imageTopicName>
        <cameraInfoTopicName>camera_info</cameraInfoTopicName>
        <frameName>/camera_front_link</frameName>
        <!--<rightFrameName>right_camera_optical_frame</rightFrameName>-->
        <hackBaseline>0.076</hackBaseline>
        <distortionK1>0.0</distortionK1>
        <distortionK2>0.0</distortionK2>
        <distortionK3>0.0</distortionK3>
        <distortionT1>0.0</distortionT1>
        <distortionT2>0.0</distortionT2>
      </plugin>
    </sensor>
  </gazebo>
  <gazebo>
    <plugin filename="librotors_gazebo_mavlink_interface.so" name="mavlink_interface">
      <robotNamespace></robotNamespace>
      <imuSubTopic>/imu</imuSubTopic>
      <gpsSubTopic>/gps</gpsSubTopic>
      <mavlink_addr>INADDR_ANY</mavlink_addr>
      <mavlink_udp_port>14560</mavlink_udp_port>
      <serialEnabled>false</serialEnabled>
      <serialDevice>/dev/ttyACM0</serialDevice>
      <baudRate>921600</baudRate>
      <qgc_addr>INADDR_ANY</qgc_addr>
      <qgc_udp_port>14550</qgc_udp_port>
      <hil_mode>false</hil_mode>
      <hil_state_level>false</hil_state_level>
      <vehicle_is_tailsitter>false</vehicle_is_tailsitter>
      <motorSpeedCommandPubTopic>/gazebo/command/motor_speed</motorSpeedCommandPubTopic>
      <control_channels>
        <channel name="rotor1">
          <input_index>0</input_index>
          <input_offset>0</input_offset>
          <input_scaling>1000</input_scaling>
          <zero_position_disarmed>0</zero_position_disarmed>
          <zero_position_armed>100</zero_position_armed>
          <joint_control_type>velocity</joint_control_type>
        </channel>
        <channel name="rotor2">
          <input_index>1</input_index>
          <input_offset>0</input_offset>
          <input_scaling>1000</input_scaling>
          <zero_position_disarmed>0</zero_position_disarmed>
          <zero_position_armed>100</zero_position_armed>
          <joint_control_type>velocity</joint_control_type>
        </channel>
        <channel name="rotor3">
          <input_index>2</input_index>
          <input_offset>0</input_offset>
          <input_scaling>1000</input_scaling>
          <zero_position_disarmed>0</zero_position_disarmed>
          <zero_position_armed>100</zero_position_armed>
          <joint_control_type>velocity</joint_control_type>
        </channel>
        <channel name="rotor4">
          <input_index>3</input_index>
          <input_offset>0</input_offset>
          <input_scaling>1000</input_scaling>
          <zero_position_disarmed>0</zero_position_disarmed>
          <zero_position_armed>100</zero_position_armed>
          <joint_control_type>velocity</joint_control_type>
        </channel>
        <channel name="rotor5">
          <input_index>4</input_index>
          <input_offset>1</input_offset>
          <input_scaling>324.6</input_scaling>
          <zero_position_disarmed>0</zero_position_disarmed>
          <zero_position_armed>0</zero_position_armed>
          <joint_control_type>velocity</joint_control_type>
          <joint_control_pid>
            <p>0.1</p>
            <i>0</i>
            <d>0</d>
            <iMax>0.0</iMax>
            <iMin>0.0</iMin>
            <cmdMax>2</cmdMax>
            <cmdMin>-2</cmdMin>
          </joint_control_pid>
          <joint_name>zephyr_delta_wing::propeller_joint</joint_name>
        </channel>
        <channel name="rotor6">
          <input_index>5</input_index>
          <input_offset>0</input_offset>
          <!-- joint limits [-0.524, 0.524] -->
          <input_scaling>0.524</input_scaling>
          <zero_position_disarmed>0</zero_position_disarmed>
          <zero_position_armed>0</zero_position_armed>
          <joint_control_type>position</joint_control_type>
          <joint_name>zephyr_delta_wing::flap_left_joint</joint_name>
          <joint_control_pid>
            <p>10.0</p>
            <i>0</i>
            <d>0</d>
            <iMax>0</iMax>
            <iMin>0</iMin>
            <cmdMax>20</cmdMax>
            <cmdMin>-20</cmdMin>
          </joint_control_pid>
        </channel>
        <channel name="rotor7">
          <input_index>6</input_index>
          <input_offset>0</input_offset>
          <!-- joint limits [-0.524, 0.524] -->
          <input_scaling>0.524</input_scaling>
          <zero_position_disarmed>0</zero_position_disarmed>
          <zero_position_armed>0</zero_position_armed>
          <joint_control_type>position</joint_control_type>
          <joint_name>zephyr_delta_wing::flap_right_joint</joint_name>
          <joint_control_pid>
            <p>10.0</p>
            <i>0</i>
            <d>0</d>
            <iMax>0</iMax>
            <iMin>0</iMin>
            <cmdMax>20</cmdMax>
            <cmdMin>-20</cmdMin>
          </joint_control_pid>
        </channel>
        <channel name="rotor8">
          <input_index>7</input_index>
          <input_offset>0</input_offset>
          <input_scaling>0.524</input_scaling>
          <zero_position_disarmed>0</zero_position_disarmed>
          <zero_position_armed>0</zero_position_armed>
          <joint_control_type>position</joint_control_type>
        </channel>
      </control_channels>
    </plugin>
  </gazebo>
  <!-- IMU link -->
  <link name="/imu_link">
    <inertial>
      <inertia ixx="0.00001" ixy="0.0" ixz="0.0" iyy="0.00001" iyz="0.0" izz="0.00001"/>
      <mass value="0.015"/>
      <!-- [kg] -->
      <origin rpy="0 0 0" xyz="0 0 0"/>
    </inertial>
  </link>
  <!-- IMU joint -->
  <joint name="/imu_joint" type="revolute">
    <origin rpy="0 0 0" xyz="0 0 0"/>
    <parent link="base_link"/>
    <child link="/imu_link"/>
    <limit effort="0" lower="0" upper="0" velocity="0"/>
  </joint>
  <gazebo>
    <plugin filename="librotors_gazebo_imu_plugin.so" name="rotors_gazebo_imu_plugin">
      <!-- A good description of the IMU parameters can be found in the kalibr documentation:
           https://github.com/ethz-asl/kalibr/wiki/IMU-Noise-Model-and-Intrinsics -->
      <robotNamespace></robotNamespace>
      <!-- (string, required): ros namespace in which the messages are published -->
      <linkName>/imu_link</linkName>
      <!-- (string, required): name of the body which holds the IMU sensor -->
      <imuTopic>/imu</imuTopic>
      <!-- (string): name of the sensor output topic and prefix of service names (defaults to imu) -->
      <gyroscopeNoiseDensity>0.0003394</gyroscopeNoiseDensity>
      <!-- Gyroscope noise density (two-sided spectrum) [rad/s/sqrt(Hz)] -->
      <gyroscopeRandomWalk>3.8785e-05</gyroscopeRandomWalk>
      <!-- Gyroscope bias random walk [rad/s/s/sqrt(Hz)] -->
      <gyroscopeBiasCorrelationTime>1000.0</gyroscopeBiasCorrelationTime>
      <!-- Gyroscope bias correlation time constant [s] -->
      <gyroscopeTurnOnBiasSigma>0.0087</gyroscopeTurnOnBiasSigma>
      <!-- Gyroscope turn on bias standard deviation [rad/s] -->
      <accelerometerNoiseDensity>0.004</accelerometerNoiseDensity>
      <!-- Accelerometer noise density (two-sided spectrum) [m/s^2/sqrt(Hz)] -->
      <accelerometerRandomWalk>0.006</accelerometerRandomWalk>
      <!-- Accelerometer bias random walk. [m/s^2/s/sqrt(Hz)] -->
      <accelerometerBiasCorrelationTime>300.0</accelerometerBiasCorrelationTime>
      <!-- Accelerometer bias correlation time constant [s] -->
      <accelerometerTurnOnBiasSigma>0.196</accelerometerTurnOnBiasSigma>
      <!-- Accelerometer turn on bias standard deviation [m/s^2] -->
    </plugin>
  </gazebo>
  <!-- IMU link -->
  <link name="/imugt_link">
    <inertial>
      <inertia ixx="0.00001" ixy="0.0" ixz="0.0" iyy="0.00001" iyz="0.0" izz="0.00001"/>
      <mass value="1e-05"/>
      <!-- [kg] -->
      <origin rpy="0 0 0" xyz="0 0 0"/>
    </inertial>
  </link>
  <!-- IMU joint -->
  <joint name="/imugt_joint" type="revolute">
    <origin rpy="0 0 0" xyz="0 0 0"/>
    <parent link="base_link"/>
    <child link="/imugt_link"/>
    <limit effort="0" lower="0" upper="0" velocity="0"/>
  </joint>
  <gazebo>
    <plugin filename="librotors_gazebo_imu_plugin.so" name="rotors_gazebo_imugt_plugin">
      <!-- A good description of the IMU parameters can be found in the kalibr documentation:
           https://github.com/ethz-asl/kalibr/wiki/IMU-Noise-Model-and-Intrinsics -->
      <robotNamespace></robotNamespace>
      <!-- (string, required): ros namespace in which the messages are published -->
      <linkName>/imugt_link</linkName>
      <!-- (string, required): name of the body which holds the IMU sensor -->
      <imuTopic>ground_truth/imu</imuTopic>
      <!-- (string): name of the sensor output topic and prefix of service names (defaults to imu) -->
      <gyroscopeNoiseDensity>0.0</gyroscopeNoiseDensity>
      <!-- Gyroscope noise density (two-sided spectrum) [rad/s/sqrt(Hz)] -->
      <gyroscopeRandomWalk>0.0</gyroscopeRandomWalk>
      <!-- Gyroscope bias random walk [rad/s/s/sqrt(Hz)] -->
      <gyroscopeBiasCorrelationTime>1000.0</gyroscopeBiasCorrelationTime>
      <!-- Gyroscope bias correlation time constant [s] -->
      <gyroscopeTurnOnBiasSigma>0.0</gyroscopeTurnOnBiasSigma>
      <!-- Gyroscope turn on bias standard deviation [rad/s] -->
      <accelerometerNoiseDensity>0.0</accelerometerNoiseDensity>
      <!-- Accelerometer noise density (two-sided spectrum) [m/s^2/sqrt(Hz)] -->
      <accelerometerRandomWalk>0.0</accelerometerRandomWalk>
      <!-- Accelerometer bias random walk. [m/s^2/s/sqrt(Hz)] -->
      <accelerometerBiasCorrelationTime>300.0</accelerometerBiasCorrelationTime>
      <!-- Accelerometer bias correlation time constant [s] -->
      <accelerometerTurnOnBiasSigma>0.0</accelerometerTurnOnBiasSigma>
      <!-- Accelerometer turn on bias standard deviation [m/s^2] -->
    </plugin>
  </gazebo>
  <!-- odometry link -->
  <link name="/ground_truth/odometry_sensorgt_link">
    <inertial>
      <inertia ixx="0.00001" ixy="0.0" ixz="0.0" iyy="0.00001" iyz="0.0" izz="0.00001"/>
      <mass value="1e-05"/>
      <!-- [kg] -->
    </inertial>
  </link>
  <!-- odometry joint -->
  <joint name="/ground_truth/odometry_sensorgt_joint" type="revolute">
    <parent link="base_link"/>
    <origin rpy="0.0 0.0 0.0" xyz="0.0 0.0 0.0"/>
    <child link="/ground_truth/odometry_sensorgt_link"/>
    <limit effort="0" lower="0" upper="0" velocity="0"/>
  </joint>
  <gazebo>
    <plugin filename="librotors_gazebo_odometry_plugin.so" name="odometry_sensorgt">
      <linkName>/ground_truth/odometry_sensorgt_link</linkName>
      <robotNamespace>/ground_truth</robotNamespace>
      <poseTopic>pose</poseTopic>
      <poseWithCovarianceTopic>pose_with_covariance</poseWithCovarianceTopic>
      <positionTopic>position</positionTopic>
      <transformTopic>transform</transformTopic>
      <odometryTopic>odometry</odometryTopic>
      <parentFrameId>world</parentFrameId>
      <!-- Use the scoped link name here. e.g. Model::link. -->
      <measurementDivisor>1</measurementDivisor>
      <!-- only every (seq % measurementDivisor) == 0 measurement is published [int] -->
      <measurementDelay>0</measurementDelay>
      <!-- time that measurement gets held back before it's published in [simulation cycles (int)] -->
      <unknownDelay>0.0</unknownDelay>
      <!-- additional delay, that just gets added to the timestamp [s] -->
      <noiseNormalPosition>0 0 0</noiseNormalPosition>
      <!-- standard deviation of additive white gaussian noise [m] -->
      <noiseNormalQuaternion>0 0 0</noiseNormalQuaternion>
      <!-- standard deviation white gaussian noise [rad]: q_m = q*quaternionFromSmallAngleApproximation(noiseNormalQ) -->
      <noiseNormalLinearVelocity>0 0 0</noiseNormalLinearVelocity>
      <!-- standard deviation of additive white gaussian noise [m/s] -->
      <noiseNormalAngularVelocity>0 0 0</noiseNormalAngularVelocity>
      <!-- standard deviation of additive white gaussian noise [rad/s] -->
      <noiseUniformPosition>0 0 0</noiseUniformPosition>
      <!-- symmetric bounds of uniform noise [m] -->
      <noiseUniformQuaternion>0 0 0</noiseUniformQuaternion>
      <!-- symmetric bounds of uniform noise [rad], computation see above -->
      <noiseUniformLinearVelocity>0 0 0</noiseUniformLinearVelocity>
      <!-- symmetric bounds of uniform noise [m/s] -->
      <noiseUniformAngularVelocity>0 0 0</noiseUniformAngularVelocity>
    </plugin>
  </gazebo>
  <gazebo>
    <plugin filename="librotors_gazebo_bag_plugin.so" name="rosbag">
      <robotNamespace></robotNamespace>
      <bagFileName>noir</bagFileName>
      <linkName>base_link</linkName>
      <frameId>base_link</frameId>
      <commandAttitudeThrustSubTopic>command/attitude</commandAttitudeThrustSubTopic>
      <commandAttitudeThrustPubTopic>command/attitude</commandAttitudeThrustPubTopic>
      <rotorVelocitySlowdownSim>10</rotorVelocitySlowdownSim>
    </plugin>
  </gazebo>
</robot>
